<?xml version="1.0" ?>
<!-- =================================================================================== -->
<!-- |    This document was autogenerated by xacro from robot.urdf.xacro               | -->
<!-- |    EDITING THIS FILE BY HAND IS NOT RECOMMENDED                                 | -->
<!-- =================================================================================== -->
<robot name="robot">
  <material name="brown">
    <color rgba="0.02 0.005 0 1"/>
  </material>
  <material name="yellow">
    <color rgba="0.6 0.4 0 1"/>
  </material>
  <material name="black">
    <color rgba="0 0 0 1"/>
  </material>
  <link name="base_link">
</link>
  <link name="base_footprint">
</link>
  <joint name="base_footprint_joint" type="fixed">
    <parent link="base_link"/>
    <child link="base_footprint"/>
    <origin rpy="0 0 0" xyz="0 0 -0.19"/>
  </joint>
  <link name="legging">
    <visual>
      <geometry>
        <box size="0.05 0.45 0.05"/>
      </geometry>
      <material name="brown"/>
    </visual>
    <collision>
      <geometry>
        <box size="0.05 0.45 0.05"/>
      </geometry>
    </collision>
    <inertial>
      <mass value="0.1"/>
      <inertia ixx="0.0017083333333333334" ixy="0.0" ixz="0.0" iyy="4.166666666666667e-05" iyz="0.0" izz="0.0017083333333333334"/>
    </inertial>
  </link>
  <joint name="base_link_to_legging" type="fixed">
    <parent link="base_link"/>
    <child link="legging"/>
    <origin xyz="0 0 0.43333333333333335"/>
  </joint>
  <link name="right_side">
    <visual>
      <geometry>
        <box size="0.05 0.05 0.65"/>
      </geometry>
      <origin xyz="0 0 -0.10833333333333334"/>
      <material name="brown"/>
    </visual>
    <collision>
      <geometry>
        <box size="0.05 0.05 0.65"/>
      </geometry>
      <origin xyz="0 0 -0.10833333333333334"/>
    </collision>
    <inertial>
      <mass value="0.5"/>
      <inertia ixx="0.017708333333333333" ixy="0.0" ixz="0.0" iyy="0.017708333333333333" iyz="0.0" izz="0.00020833333333333335"/>
      <origin xyz="0 0 -0.10833333333333334"/>
    </inertial>
  </link>
  <joint name="legging_to_right_side" type="fixed">
    <parent link="legging"/>
    <child link="right_side"/>
    <origin xyz="0 0.25 0"/>
  </joint>
  <link name="left_side">
    <visual>
      <geometry>
        <box size="0.05 0.05 0.65"/>
      </geometry>
      <origin xyz="0 0 -0.10833333333333334"/>
      <material name="brown"/>
    </visual>
    <collision>
      <geometry>
        <box size="0.05 0.05 0.65"/>
      </geometry>
      <origin xyz="0 0 -0.10833333333333334"/>
    </collision>
    <inertial>
      <mass value="0.5"/>
      <inertia ixx="0.017708333333333333" ixy="0.0" ixz="0.0" iyy="0.017708333333333333" iyz="0.0" izz="0.00020833333333333335"/>
      <origin xyz="0 0 -0.10833333333333334"/>
    </inertial>
  </link>
  <joint name="legging_to_left_side" type="fixed">
    <parent link="legging"/>
    <child link="left_side"/>
    <origin xyz="0 -0.25 0"/>
  </joint>
  <link name="right_leg">
    <visual>
      <geometry>
        <box size="0.65 0.05 0.05"/>
      </geometry>
      <origin xyz="0 0 -0.025"/>
      <material name="brown"/>
    </visual>
    <collision>
      <geometry>
        <box size="0.65 0.05 0.05"/>
      </geometry>
      <origin xyz="0 0 -0.025"/>
    </collision>
    <inertial>
      <mass value="0.5"/>
      <inertia ixx="0.00020833333333333335" ixy="0.0" ixz="0.0" iyy="0.017708333333333333" iyz="0.0" izz="0.017708333333333333"/>
      <origin xyz="0 0 -0.025"/>
    </inertial>
  </link>
  <joint name="right_side_to_right_leg" type="fixed">
    <parent link="right_side"/>
    <child link="right_leg"/>
    <origin xyz="0 0 -0.43333333333333335"/>
  </joint>
  <link name="left_leg">
    <visual>
      <geometry>
        <box size="0.65 0.05 0.05"/>
      </geometry>
      <origin xyz="0 0 -0.025"/>
      <material name="brown"/>
    </visual>
    <collision>
      <geometry>
        <box size="0.65 0.05 0.05"/>
      </geometry>
      <origin xyz="0 0 -0.025"/>
    </collision>
    <inertial>
      <mass value="0.5"/>
      <inertia ixx="0.00020833333333333335" ixy="0.0" ixz="0.0" iyy="0.017708333333333333" iyz="0.0" izz="0.017708333333333333"/>
      <origin xyz="0 0 -0.025"/>
    </inertial>
  </link>
  <joint name="left_side_to_left_leg" type="fixed">
    <parent link="left_side"/>
    <child link="left_leg"/>
    <origin xyz="0 0 -0.43333333333333335"/>
  </joint>
  <link name="right_seat_mount">
    <visual>
      <geometry>
        <box size="0.65 0.05 0.05"/>
      </geometry>
      <origin xyz="0 0 0.025"/>
      <material name="brown"/>
    </visual>
    <collision>
      <geometry>
        <box size="0.65 0.05 0.05"/>
      </geometry>
      <origin xyz="0 0 0.025"/>
    </collision>
    <inertial>
      <mass value="0.1"/>
      <inertia ixx="4.166666666666667e-05" ixy="0.0" ixz="0.0" iyy="0.003541666666666667" iyz="0.0" izz="0.003541666666666667"/>
      <origin xyz="0 0 0.025"/>
    </inertial>
  </link>
  <joint name="right_side_to_right_seat_mount" type="fixed">
    <parent link="right_side"/>
    <child link="right_seat_mount"/>
    <origin xyz="0 0 0.21666666666666667"/>
  </joint>
  <link name="left_seat_mount">
    <visual>
      <geometry>
        <box size="0.65 0.05 0.05"/>
      </geometry>
      <origin xyz="0 0 0.025"/>
      <material name="brown"/>
    </visual>
    <collision>
      <geometry>
        <box size="0.65 0.05 0.05"/>
      </geometry>
      <origin xyz="0 0 0.025"/>
    </collision>
    <inertial>
      <mass value="0.1"/>
      <inertia ixx="4.166666666666667e-05" ixy="0.0" ixz="0.0" iyy="0.003541666666666667" iyz="0.0" izz="0.003541666666666667"/>
      <origin xyz="0 0 0.025"/>
    </inertial>
  </link>
  <joint name="left_side_to_left_seat_mount" type="fixed">
    <parent link="left_side"/>
    <child link="left_seat_mount"/>
    <origin xyz="0 0 0.21666666666666667"/>
  </joint>
  <link name="right_backrest_mount">
    <visual>
      <geometry>
        <box size="0.05 0.05 0.55"/>
      </geometry>
      <origin xyz="0 0 0.275"/>
      <material name="brown"/>
    </visual>
    <collision>
      <geometry>
        <box size="0.05 0.05 0.55"/>
      </geometry>
      <origin xyz="0 0 0.275"/>
    </collision>
    <inertial>
      <mass value="0.1"/>
      <inertia ixx="0.002541666666666667" ixy="0.0" ixz="0.0" iyy="0.002541666666666667" iyz="0.0" izz="4.166666666666667e-05"/>
      <origin xyz="0 0 0.275"/>
    </inertial>
  </link>
  <joint name="right_backrest_mount_to_right_seat_mount" type="fixed">
    <parent link="right_seat_mount"/>
    <child link="right_backrest_mount"/>
    <origin xyz="-0.3 0 0.05"/>
  </joint>
  <link name="left_backrest_mount">
    <visual>
      <geometry>
        <box size="0.05 0.05 0.55"/>
      </geometry>
      <origin xyz="0 0 0.275"/>
      <material name="brown"/>
    </visual>
    <collision>
      <geometry>
        <box size="0.05 0.05 0.55"/>
      </geometry>
      <origin xyz="0 0 0.275"/>
    </collision>
    <inertial>
      <mass value="0.1"/>
      <inertia ixx="0.002541666666666667" ixy="0.0" ixz="0.0" iyy="0.002541666666666667" iyz="0.0" izz="4.166666666666667e-05"/>
      <origin xyz="0 0 0.275"/>
    </inertial>
  </link>
  <joint name="left_backrest_mount_to_left_seat_mount" type="fixed">
    <parent link="left_seat_mount"/>
    <child link="left_backrest_mount"/>
    <origin xyz="-0.3 0 0.05"/>
  </joint>
  <link name="seat">
    <visual>
      <geometry>
        <box size="0.65 0.65 0.01"/>
      </geometry>
      <origin xyz="0.05 0 0"/>
      <material name="yellow"/>
    </visual>
    <collision>
      <geometry>
        <box size="0.65 0.65 0.01"/>
      </geometry>
      <origin xyz="0.05 0 0"/>
    </collision>
    <inertial>
      <mass value="0.01"/>
      <inertia ixx="0.0003521666666666667" ixy="0.0" ixz="0.0" iyy="0.0003521666666666667" iyz="0.0" izz="0.0007041666666666667"/>
      <origin xyz="0.05 0 0"/>
    </inertial>
  </link>
  <joint name="legging_to_seat" type="fixed">
    <parent link="legging"/>
    <child link="seat"/>
    <origin xyz="0 0 0.27166666666666667"/>
  </joint>
  <link name="backrest">
    <visual>
      <geometry>
        <box size="0.01 0.65 0.32083333333333336"/>
      </geometry>
      <material name="yellow"/>
    </visual>
    <collision>
      <geometry>
        <box size="0.01 0.65 0.32083333333333336"/>
      </geometry>
    </collision>
    <inertial>
      <mass value="0.01"/>
      <inertia ixx="0.00043786168981481486" ixy="0.0" ixz="0.0" iyy="8.586168981481484e-05" iyz="0.0" izz="0.0003521666666666667"/>
    </inertial>
  </link>
  <joint name="legging_to_backrest" type="fixed">
    <parent link="legging"/>
    <child link="backrest"/>
    <origin xyz="-0.27 0 0.7316666666666667"/>
  </joint>
  <link name="front_right_wheel">
    <visual>
      <geometry>
        <cylinder length="0.05" radius="0.07"/>
      </geometry>
      <material name="black"/>
    </visual>
    <collision>
      <geometry>
        <sphere radius="0.07"/>
      </geometry>
    </collision>
    <inertial>
      <mass value="0.5"/>
      <inertia ixx="0.0007166666666666668" ixy="0.0" ixz="0.0" iyy="0.0007166666666666668" iyz="0.0" izz="0.0012250000000000002"/>
    </inertial>
  </link>
  <joint name="front_right_wheel_joint" type="continuous">
    <parent link="base_link"/>
    <child link="front_right_wheel"/>
    <axis xyz="0 0 -1"/>
    <origin rpy="1.5707963267948966 0 0" xyz="0.26 -0.25 -0.085"/>
  </joint>
  <link name="rear_right_wheel">
    <visual>
      <geometry>
        <cylinder length="0.05" radius="0.07"/>
      </geometry>
      <material name="black"/>
    </visual>
    <collision>
      <geometry>
        <sphere radius="0.07"/>
      </geometry>
    </collision>
    <inertial>
      <mass value="0.5"/>
      <inertia ixx="0.0007166666666666668" ixy="0.0" ixz="0.0" iyy="0.0007166666666666668" iyz="0.0" izz="0.0012250000000000002"/>
    </inertial>
  </link>
  <joint name="rear_right_wheel_joint" type="continuous">
    <parent link="base_link"/>
    <child link="rear_right_wheel"/>
    <axis xyz="0 0 -1"/>
    <origin rpy="1.5707963267948966 0 0" xyz="-0.26 -0.25 -0.085"/>
  </joint>
  <link name="front_left_wheel">
    <visual>
      <geometry>
        <cylinder length="0.05" radius="0.07"/>
      </geometry>
      <material name="black"/>
    </visual>
    <collision>
      <geometry>
        <sphere radius="0.07"/>
      </geometry>
    </collision>
    <inertial>
      <mass value="0.5"/>
      <inertia ixx="0.0007166666666666668" ixy="0.0" ixz="0.0" iyy="0.0007166666666666668" iyz="0.0" izz="0.0012250000000000002"/>
    </inertial>
  </link>
  <joint name="front_left_wheel_joint" type="continuous">
    <parent link="base_link"/>
    <child link="front_left_wheel"/>
    <axis xyz="0 0 1"/>
    <origin rpy="-1.5707963267948966 0 0" xyz="0.26 0.25 -0.085"/>
  </joint>
  <link name="rear_left_wheel">
    <visual>
      <geometry>
        <cylinder length="0.05" radius="0.07"/>
      </geometry>
      <material name="black"/>
    </visual>
    <collision>
      <geometry>
        <sphere radius="0.07"/>
      </geometry>
    </collision>
    <inertial>
      <mass value="0.5"/>
      <inertia ixx="0.0007166666666666668" ixy="0.0" ixz="0.0" iyy="0.0007166666666666668" iyz="0.0" izz="0.0012250000000000002"/>
    </inertial>
  </link>
  <joint name="rear_left_wheel_joint" type="continuous">
    <parent link="base_link"/>
    <child link="rear_left_wheel"/>
    <axis xyz="0 0 1"/>
    <origin rpy="-1.5707963267948966 0 0" xyz="-0.26 0.25 -0.085"/>
  </joint>
</robot>
